Workbook
Name Slicer_Customer_Type: #N/A
Name Slicer_Fuel_Type: #N/A
Name Slicer_Month: #N/A
Name Slicer_Region: #N/A
Name Slicer_Year: #N/A

Sheet Pivot 1
A1: Count of Order_ID | C1: Sum of Price(in lakh) | E1: Average of Discount% | G1: Average of Price(in lakh) | I1: Average of Rating_1_to_5 | K1: Row Labels | L1: Sum of Price(in lakh) | N1: Row Labels | O1: Count of Order_ID
A2: 1000 | C2: 9370.91 | E2: 0.018917686 | G2: 9.37091 | I2: 3.8537549 | K2: Pune | L2: 638.88 | N2: Audi | O2: 1
K3: Ludhiana | L3: 568.27 | N3: Honda | O3: 54
A4: Row Labels | B4: Count of Order_ID | D4: Row Labels | E4: Sum of Price(in lakh) | G4: Row Labels | H4: Count of Order_ID | I4: Average of Delivery_time | K4: Bhubaneswar | L4: 525.85 | N4: Hyundai | O4: 182
A5: Cancelled | B5: 51 | D5: Hyundai | E5: 1748.02 | F5: =GETPIVOTDATA("Price(in lakh)",$D$4,"Brand","Hyundai")/GETPIVOTDATA("Price(in lakh)",$D$4) -> 0.22931288 | G5: i10 Nios | H5: 33 | I5: 19.186966 | K5: Guwahati | L5: 447.9 | N5: Kia | O5: 64
A6: Delivered | B6: 936 | D6: Kia | E6: 713.53 | F6: =GETPIVOTDATA("Price(in lakh)",$D$4,"Brand","Kia")/GETPIVOTDATA("Price(in lakh)",$D$4) -> 0.093603975 | G6: Creta | H6: 34 | K6: Surat | L6: 436.28 | N6: Mahindra | O6: 86
A7: Pending Delivery | B7: 13 | D7: Mahindra | E7: 1010.6 | F7: =GETPIVOTDATA("Price(in lakh)",$D$4,"Brand","Mahindra")/GETPIVOTDATA("Price(in lakh)",$D$4) -> 0.13257491 | G7: i20 | H7: 41 | K7: Bhopal | L7: 429.37 | N7: Maruti Suzuki | O7: 360
A8: Grand Total | B8: 1000 | D8: Maruti Suzuki | E8: 2718.05 | F8: =GETPIVOTDATA("Price(in lakh)",$D$4,"Brand","Maruti Suzuki")/GETPIVOTDATA("Price(in lakh)",$D$4) -> 0.35656565 | G8: Punch | H8: 47 | K8: Mysuru | L8: 425.6 | N8: Mercedes-Benz | O8: 1
A9: Cancellation Rate | B9: =GETPIVOTDATA("Order_ID",$A$4,"Order_Status","Cancelled")/GETPIVOTDATA("Order_ID",$A$4) -> 0.051 | D9: Tata | E9: 1432.66 | F9: =GETPIVOTDATA("Price(in lakh)",$D$4,"Brand","Tata")/GETPIVOTDATA("Price(in lakh)",$D$4) -> 0.18794258 | G9: Nexon | H9: 50 | K9: Chandigarh | L9: 406.46 | N9: MG | O9: 23
D10: Grand Total | E10: 7622.86 | G10: Brezza | H10: 53 | K10: Ahmedabad | L10: 405.85 | N10: Renault | O10: 25
G11: Ertiga | H11: 56 | K11: Panipat | L11: 401.81 | N11: Skoda | O11: 16
A12: Sum of Price(in lakh) | B12: Column Labels | G12: Swift | H12: 57 | K12: Grand Total | L12: 4686.27 | N12: Tata | O12: 163
A13: Row Labels | B13: 2024 | C13: 2025 | D13: 2026 | E13: Grand Total | G13: Baleno | H13: 70 | N13: Toyota | O13: 12
A14: Jan | B14: 245.25 | C14: 159.71 | D14: 264.5 | E14: 669.46 | G14: Dzire | H14: 76 | K14: Row Labels | L14: Sum of Price(in lakh) | N14: Volkswagen | O14: 13
A15: Feb | B15: 184.66 | C15: 226.36 | D15: 237.22 | E15: 648.24 | G15: Grand Total | H15: 517 | K15: Hatchback | L15: 1737.9 | N15: Grand Total | O15: 1000
A16: Mar | B16: 240.19 | C16: 367.68 | D16: 361.21 | E16: 969.08 | K16: Luxury Sedan | L16: 62
A17: Apr | B17: 338.24 | C17: 308.57 | D17: 407.79 | E17: 1054.6 | K17: Luxury SUV | L17: 54 | N17: Row Labels | O17: Sum of Price(in lakh)
A18: May | B18: 218.58 | C18: 236.05 | D18: 173.2 | E18: 627.83 | K18: MPV | L18: 847.22 | N18: Harsh Nair | O18: 342.86
A19: Jun | B19: 198.21 | C19: 310.15 | D19: 275.1 | E19: 783.46 | K19: Sedan | L19: 1789.07 | N19: Gaurav Shah | O19: 270.58
A20: Jul | B20: 228.46 | C20: 245.15 | D20: 261.99 | E20: 735.6 | G20: Row Labels | H20: Count of Order_ID | I20: Sum of Price(in lakh) | K20: SUV | L20: 4880.72 | N20: Arjun Reddy | O20: 241.02
A21: Aug | B21: 231.96 | C21: 284.84 | D21: 364.77 | E21: 881.57 | G21: North | H21: 289 | I21: 2763.74 | K21: Grand Total | L21: 9370.91 | N21: Akash Verma | O21: 239.07
A22: Sep | B22: 205.31 | C22: 268.62 | D22: 349.71 | E22: 823.64 | G22: West | H22: 228 | I22: 2089.29 | N22: Varun Yadav | O22: 232.36
A23: Oct | B23: 353.8 | C23: 494.05 | E23: 847.85 | G23: South | H23: 230 | I23: 2088.76 | K23: Row Labels | L23: Sum of Price(in lakh) | N23: Akash Jain | O23: 216.32
A24: Nov | B24: 323.53 | C24: 360.72 | E24: 684.25 | G24: East | H24: 176 | I24: 1674.73 | K24: Patna Autoplex | L24: 520.79 | N24: Yash Sharma | O24: 215.35
A25: Dec | B25: 283.96 | C25: 361.37 | E25: 645.33 | G25: Central | H25: 77 | I25: 754.39 | K25: Ludhiana Wheels | L25: 519.46 | N25: Tarun Sharma | O25: 207.57
A26: Grand Total | B26: 3052.15 | C26: 3623.27 | D26: 2695.49 | E26: 9370.91 | G26: Grand Total | H26: 1000 | I26: 9370.91 | K26: Bengaluru Auto Hub | L26: 494.96 | N26: Nitin Pillai | O26: 207.14
K27: Pune Autoplex | L27: 477.79 | N27: Akash Pillai | O27: 203.07
G28: Row Labels | H28: Count of Order_ID | K28: Bhubaneswar Motors | L28: 472.53 | N28: Grand Total | O28: 2375.34
A29: Row Labels | B29: Count of Order_ID | D29: Row Labels | E29: Count of Order_ID | G29: Business Owner | H29: 183 | K29: Indore Wheels | L29: 464.54
A30: Social Media | B30: 157 | D30: After-Sales Support | E30: 24 | G30: Doctor | H30: 43 | K30: Surat Autoplex | L30: 454.99
A31: Referral | B31: 151 | D31: Delivery Delay | E31: 31 | G31: Engineer | H31: 101 | K31: Guwahati Automobiles | L31: 423.22
A32: Corporate Tie-up | B32: 143 | D32: Pricing | E32: 24 | G32: Farmer | H32: 49 | K32: Noida Car World | L32: 413.82
A33: Online Website | B33: 142 | D33: Sales Experience | E33: 22 | G33: Retired | H33: 47 | K33: Nagpur Motors | L33: 407.8
A34: Auto Expo/Event | B34: 140 | D34: Vehicle Quality | E34: 31 | G34: Salaried - Government | H34: 111 | K34: Grand Total | L34: 4649.9
A35: Walk-in | B35: 138 | D35: Grand Total | E35: 132 | G35: Salaried - Private | H35: 296
A36: Test Drive Campaign | B36: 129 | G36: Self-Employed Professional | H36: 99
A37: Grand Total | B37: 1000 | G37: Student/Other | H37: 13
G38: Teacher | H38: 58
G39: Grand Total | H39: 1000
A42: Count of Target Achieved | B42: Column Labels | G42: Row Labels | H42: Sum of Price(in lakh)
...

Sheet Executive

Sheet Insights

Sheet Key Findings

Sheet Sales
A1: Order_ID | B1: Order_Date | C1: Month | D1: Year | E1: Delivery_Date | F1: Order_Status | G1: Delivery_time | H1: Customer_ID | I1: Customer_Name | J1: Gender | K1: Age | L1: City | M1: State | N1: Occupation | O1: Annual_Income_INR | P1: Customer_Type | Q1: Car_ID | R1: Brand | S1: Model | T1: Segment | U1: Fuel_Type | V1: Transmission | W1: Ex_Showroom_Price_INR | X1: Launch_Year | Y1: Warranty_Years | Z1: Dealer_ID | AA1: Region | AB1: Dealer_Name | AC1: Established_Year | AD1: Showroom_Area_SqFt | AE1: Dealer_Rating | AF1: Salesperson_ID | AG1: Salesperson_Name | AH1: Monthly_Target_Units | AI1: Target Achieved | AJ1: Color | AK1: Discount% | AL1: Discount_INR | AM1: Price | AN1: Price(in lakh) | AO1: Payment_Mode | AP1: Finance_Provider | AQ1: Lead_Source | AR1: Insurance_Bundled | AS1: Feedback_ID | AT1: Rating_1_to_5 | AU1: Recommend_Score_0_to_10 | AV1: Feedback_Channel | AW1: Complaint_Category
A2: ORD00001 | B2: 45294 | C2: =TEXT(B2,"mmm") -> Jan | D2: =TEXT(B2,"yyyy") -> 2024 | E2: 45309 | F2: Delivered | G2: =IF(E2=0,"",E2-B2) -> 15 | H2: CU0692 | I2: =VLOOKUP($H2,Customers!$A$1:$I$721,2,FALSE) -> Sachin Pillai | J2: =VLOOKUP($H2,Customers!$A$1:$I$721,3,FALSE) -> Male | K2: =VLOOKUP($H2,Customers!$A$1:$I$721,4,FALSE) -> 41 | L2: =VLOOKUP($H2,Customers!$A$1:$I$721,5,FALSE) -> Chandigarh | M2: =VLOOKUP($H2,Customers!$A$1:$I$721,6,FALSE) -> Chandigarh | N2: =VLOOKUP($H2,Customers!$A$1:$I$721,7,FALSE) -> Salaried - Government | O2: =VLOOKUP($H2,Customers!$A$1:$I$721,8,FALSE) -> 1020000 | P2: =VLOOKUP($H2,Customers!$A$1:$I$721,9,FALSE) -> Individual | Q2: C024 | R2: {=VLOOKUP($Q2,Cars[],{2,3,4,5,6,7,8,9},FALSE)} -> Mahindra | S2: Bolero | T2: SUV | U2: Diesel | V2: Manual | W2: 1000000 | X2: 2019 | Y2: 3 | Z2: D004 | AA2: =VLOOKUP(Z2,Dealers[],5,FALSE) -> North | AB2: {=VLOOKUP($Z2,Dealers[],{2,7,8,9},FALSE)} -> Chandigarh Car World | AC2: 2018 | AD2: 4500 | AE2: 4 | AF2: S012 | AG2: =VLOOKUP($AF2,SalesPerson[],2,FALSE) -> Tarun Sharma | AH2: =_xlfn.XLOOKUP(AG2,Salespersons!$B:$B,Salespersons!$G:$G,,0) -> 7 | AI2: =_xlfn.XLOOKUP(AG2,Salespersons!$B:$B,Salespersons!$I:$I,,0) -> True | AJ2: Blue | AK2: =AL2/W2 -> 0 | AL2: 0 | AM2: =W2-AL2 -> 1000000 | AN2: =AM2/100000 -> 10 | AO2: Cash | AP2: N/A | AQ2: Online Website | AR2: No
A3: ORD00002 | B3: 45294 | C3: =TEXT(B3,"mmm") -> Jan | D3: =TEXT(B3,"yyyy") -> 2024 | E3: 45324 | F3: Delivered | G3: =IF(E3=0,"",E3-B3) -> 30 | H3: CU0522 | I3: =VLOOKUP($H3,Customers!$A$1:$I$721,2,FALSE) -> Ashok Pillai | J3: =VLOOKUP($H3,Customers!$A$1:$I$721,3,FALSE) -> Male | K3: =VLOOKUP($H3,Customers!$A$1:$I$721,4,FALSE) -> 25 | L3: =VLOOKUP($H3,Customers!$A$1:$I$721,5,FALSE) -> Ludhiana | M3: =VLOOKUP($H3,Customers!$A$1:$I$721,6,FALSE) -> Punjab | N3: =VLOOKUP($H3,Customers!$A$1:$I$721,7,FALSE) -> Salaried - Private | O3: =VLOOKUP($H3,Customers!$A$1:$I$721,8,FALSE) -> 990000 | P3: =VLOOKUP($H3,Customers!$A$1:$I$721,9,FALSE) -> Individual | Q3: C005 | R3: {=VLOOKUP($Q3,Cars[],{2,3,4,5,6,7,8,9},FALSE)} -> Maruti Suzuki | S3: Brezza | T3: SUV | U3: Petrol | V3: Automatic | W3: 900000 | X3: 2022 | Y3: 3 | Z3: D005 | AA3: =VLOOKUP(Z3,Dealers[],5,FALSE) -> North | AB3: {=VLOOKUP($Z3,Dealers[],{2,7,8,9},FALSE)} -> Ludhiana Wheels | AC3: 2010 | AD3: 12000 | AE3: 4 | AF3: S014 | AG3: =VLOOKUP($AF3,SalesPerson[],2,FALSE) -> Harsh Nair | AH3: =_xlfn.XLOOKUP(AG3,Salespersons!$B:$B,Salespersons!$G:$G,,0) -> 8 | AI3: =_xlfn.XLOOKUP(AG3,Salespersons!$B:$B,Salespersons!$I:$I,,0) -> True | AJ3: Silver | AK3: =AL3/W3 -> 0 | AL3: 0 | AM3: =W3-AL3 -> 900000 | AN3: =AM3/100000 -> 9 | AO3: Loan/Finance | AP3: HDFC Bank | AQ3: Corporate Tie-up | AR3: No | AS3: {=VLOOKUP($A3,Feedback[],{2,4,5,6,7},FALSE)} -> FB0001 | AT3: 4 | AU3: 8 | AV3: Dealer Visit | AW3: None
A4: ORD00003 | B4: 45295 | C4: =TEXT(B4,"mmm") -> Jan | D4: =TEXT(B4,"yyyy") -> 2024 | E4: 45298 | F4: Delivered | G4: =IF(E4=0,"",E4-B4) -> 3 | H4: CU0319 | I4: =VLOOKUP($H4,Customers!$A$1:$I$721,2,FALSE) -> Divya Malhotra | J4: =VLOOKUP($H4,Customers!$A$1:$I$721,3,FALSE) -> Female | K4: =VLOOKUP($H4,Customers!$A$1:$I$721,4,FALSE) -> 27 | L4: =VLOOKUP($H4,Customers!$A$1:$I$721,5,FALSE) -> Delhi | M4: =VLOOKUP($H4,Customers!$A$1:$I$721,6,FALSE) -> Delhi | N4: =VLOOKUP($H4,Customers!$A$1:$I$721,7,FALSE) -> Salaried - Government | O4: =VLOOKUP($H4,Customers!$A$1:$I$721,8,FALSE) -> 1360000 | P4: =VLOOKUP($H4,Customers!$A$1:$I$721,9,FALSE) -> Individual | Q4: C015 | R4: {=VLOOKUP($Q4,Cars[],{2,3,4,5,6,7,8,9},FALSE)} -> Tata | S4: Punch | T4: SUV | U4: Petrol | V4: Manual | W4: 650000 | X4: 2021 | Y4: 3 | Z4: D001 | AA4: =VLOOKUP(Z4,Dealers[],5,FALSE) -> North | AB4: {=VLOOKUP($Z4,Dealers[],{2,7,8,9},FALSE)} -> Delhi Autoplex | AC4: 2013 | AD4: 4500 | AE4: 3.7 | AF4: S002 | AG4: =VLOOKUP($AF4,SalesPerson[],2,FALSE) -> Nisha Iyer | AH4: =_xlfn.XLOOKUP(AG4,Salespersons!$B:$B,Salespersons!$G:$G,,0) -> 4 | AI4: =_xlfn.XLOOKUP(AG4,Salespersons!$B:$B,Salespersons!$I:$I,,0) -> True | AJ4: Silver | AK4: =AL4/W4 -> 0.016923077 | AL4: 11000 | AM4: =W4-AL4 -> 639000 | AN4: =AM4/100000 -> 6.39 | AO4: Loan/Finance | AP4: ICICI Bank | AQ4: Corporate Tie-up | AR4: No | AS4: {=VLOOKUP($A4,Feedback[],{2,4,5,6,7},FALSE)} -> FB0002 | AT4: 5 | AU4: 10 | AV4: Phone | AW4: None
A5: ORD00004 | B5: 45297 | C5: =TEXT(B5,"mmm") -> Jan | D5: =TEXT(B5,"yyyy") -> 2024 | E5: 45312 | F5: Delivered | G5: =IF(E5=0,"",E5-B5) -> 15 | H5: CU0149 | I5: =VLOOKUP($H5,Customers!$A$1:$I$721,2,FALSE) -> Jatin Saini | J5: =VLOOKUP($H5,Customers!$A$1:$I$721,3,FALSE) -> Male | K5: =VLOOKUP($H5,Customers!$A$1:$I$721,4,FALSE) -> 33 | L5: =VLOOKUP($H5,Customers!$A$1:$I$721,5,FALSE) -> Pune | M5: =VLOOKUP($H5,Customers!$A$1:$I$721,6,FALSE) -> Maharashtra | N5: =VLOOKUP($H5,Customers!$A$1:$I$721,7,FALSE) -> Business Owner | O5: =VLOOKUP($H5,Customers!$A$1:$I$721,8,FALSE) -> 2200000 | P5: =VLOOKUP($H5,Customers!$A$1:$I$721,9,FALSE) -> Individual | Q5: C002 | R5: {=VLOOKUP($Q5,Cars[],{2,3,4,5,6,7,8,9},FALSE)} -> Maruti Suzuki | S5: Swift | T5: Hatchback | U5: Petrol | V5: Manual | W5: 650000 | X5: 2024 | Y5: 3 | Z5: D011 | AA5: =VLOOKUP(Z5,Dealers[],5,FALSE) -> West | AB5: {=VLOOKUP($Z5,Dealers[],{2,7,8,9},FALSE)} -> Nagpur Motors | AC5: 2019 | AD5: 12000 | AE5: 4.6 | AF5: S034 | AG5: =VLOOKUP($AF5,SalesPerson[],2,FALSE) -> Arjun Reddy | AH5: =_xlfn.XLOOKUP(AG5,Salespersons!$B:$B,Salespersons!$G:$G,,0) -> 5 | AI5: =_xlfn.XLOOKUP(AG5,Salespersons!$B:$B,Salespersons!$I:$I,,0) -> True | AJ5: Red | AK5: =AL5/W5 -> 0.016923077 | AL5: 11000 | AM5: =W5-AL5 -> 639000 | AN5: =AM5/100000 -> 6.39 | AO5: Cash | AP5: N/A | AQ5: Referral | AR5: Yes | AS5: {=VLOOKUP($A5,Feedback[],{2,4,5,6,7},FALSE)} -> FB0003 | AT5: 3 | AU5: 4 | AV5: Dealer Visit | AW5: Vehicle Quality
A6: ORD00005 | B6: 45297 | C6: =TEXT(B6,"mmm") -> Jan | D6: =TEXT(B6,"yyyy") -> 2024 | E6: 45321 | F6: Delivered | G6: =IF(E6=0,"",E6-B6) -> 24 | H6: CU0684 | I6: =VLOOKUP($H6,Customers!$A$1:$I$721,2,FALSE) -> Ravi Verma | J6: =VLOOKUP($H6,Customers!$A$1:$I$721,3,FALSE) -> Male | K6: =VLOOKUP($H6,Customers!$A$1:$I$721,4,FALSE) -> 21 | L6: =VLOOKUP($H6,Customers!$A$1:$I$721,5,FALSE) -> Panipat | M6: =VLOOKUP($H6,Customers!$A$1:$I$721,6,FALSE) -> Haryana | N6: =VLOOKUP($H6,Customers!$A$1:$I$721,7,FALSE) -> Salaried - Government | O6: =VLOOKUP($H6,Customers!$A$1:$I$721,8,FALSE) -> 490000 | P6: =VLOOKUP($H6,Customers!$A$1:$I$721,9,FALSE) -> Individual | Q6: C010 | R6: {=VLOOKUP($Q6,Cars[],{2,3,4,5,6,7,8,9},FALSE)} -> Hyundai | S6: Venue | T6: SUV | U6: Petrol | V6: Manual | W6: 800000 | X6: 2022 | Y6: 3 | Z6: D003 | AA6: =VLOOKUP(Z6,Dealers[],5,FALSE) -> North | AB6: {=VLOOKUP($Z6,Dealers[],{2,7,8,9},FALSE)} -> Panipat Motors | AC6: 2012 | AD6: 10000 | AE6: 4.2 | AF6: S011 | AG6: =VLOOKUP($AF6,SalesPerson[],2,FALSE) -> Yash Bose | AH6: =_xlfn.XLOOKUP(AG6,Salespersons!$B:$B,Salespersons!$G:$G,,0) -> 7 | AI6: =_xlfn.XLOOKUP(AG6,Salespersons!$B:$B,Salespersons!$I:$I,,0) -> True | AJ6: Silver | AK6: =AL6/W6 -> 0.035 | AL6: 28000 | AM6: =W6-AL6 -> 772000 | AN6: =AM6/100000 -> 7.72 | AO6: Cash | AP6: N/A | AQ6: Social Media | AR6: No | AS6: {=VLOOKUP($A6,Feedback[],{2,4,5,6,7},FALSE)} -> FB0004 | AT6: 5 | AU6: 10 | AV6: Email | AW6: None
A7: ORD00006 | B7: 45298 | C7: =TEXT(B7,"mmm") -> Jan | D7: =TEXT(B7,"yyyy") -> 2024 | E7: 45330 | F7: Delivered | G7: =IF(E7=0,"",E7-B7) -> 32 | H7: CU0167 | I7: =VLOOKUP($H7,Customers!$A$1:$I$721,2,FALSE) -> Komal Patel | J7: =VLOOKUP($H7,Customers!$A$1:$I$721,3,FALSE) -> Female | K7: =VLOOKUP($H7,Customers!$A$1:$I$721,4,FALSE) -> 25 | L7: =VLOOKUP($H7,Customers!$A$1:$I$721,5,FALSE) -> Coimbatore | M7: =VLOOKUP($H7,Customers!$A$1:$I$721,6,FALSE) -> Tamil Nadu | N7: =VLOOKUP($H7,Customers!$A$1:$I$721,7,FALSE) -> Business Owner | O7: =VLOOKUP($H7,Customers!$A$1:$I$721,8,FALSE) -> 2650000 | P7: =VLOOKUP($H7,Customers!$A$1:$I$721,9,FALSE) -> Individual | Q7: C003 | R7: {=VLOOKUP($Q7,Cars[],{2,3,4,5,6,7,8,9},FALSE)} -> Maruti Suzuki | S7: Baleno | T7: Hatchback | U7: Petrol | V7: Automatic | W7: 760000 | X7: 2022 | Y7: 2 | Z7: D002 | AA7: =VLOOKUP(Z7,Dealers[],5,FALSE) -> North | AB7: {=VLOOKUP($Z7,Dealers[],{2,7,8,9},FALSE)} -> Gurugram Autoplex | AC7: 2007 | AD7: 10000 | AE7: 4 | AF7: S008 | AG7: =VLOOKUP($AF7,SalesPerson[],2,FALSE) -> Mohit Nair | AH7: =_xlfn.XLOOKUP(AG7,Salespersons!$B:$B,Salespersons!$G:$G,,0) -> 5 | AI7: =_xlfn.XLOOKUP(AG7,Salespersons!$B:$B,Salespersons!$I:$I,,0) -> True | AJ7: Grey | AK7: =AL7/W7 -> 0 | AL7: 0 | AM7: =W7-AL7 -> 760000 | AN7: =AM7/100000 -> 7.6 | AO7: Cash | AP7: N/A | AQ7: Online Website | AR7: No | AS7: {=VLOOKUP($A7,Feedback[],{2,4,5,6,7},FALSE)} -> FB0005 | AT7: 4 | AU7: 9 | AV7: Dealer Visit | AW7: None
A8: ORD00007 | B8: 45298 | C8: =TEXT(B8,"mmm") -> Jan | D8: =TEXT(B8,"yyyy") -> 2024 | E8: 45302 | F8: Delivered | G8: =IF(E8=0,"",E8-B8) -> 4 | H8: CU0340 | I8: =VLOOKUP($H8,Customers!$A$1:$I$721,2,FALSE) -> Siddharth Khanna | J8: =VLOOKUP($H8,Customers!$A$1:$I$721,3,FALSE) -> Male | K8: =VLOOKUP($H8,Customers!$A$1:$I$721,4,FALSE) -> 21 | L8: =VLOOKUP($H8,Customers!$A$1:$I$721,5,FALSE) -> Bhubaneswar | M8: =VLOOKUP($H8,Customers!$A$1:$I$721,6,FALSE) -> Odisha | N8: =VLOOKUP($H8,Customers!$A$1:$I$721,7,FALSE) -> Salaried - Private | O8: =VLOOKUP($H8,Customers!$A$1:$I$721,8,FALSE) -> 1070000 | P8: =VLOOKUP($H8,Customers!$A$1:$I$721,9,FALSE) -> Individual | Q8: C028 | R8: {=VLOOKUP($Q8,Cars[],{2,3,4,5,6,7,8,9},FALSE)} -> Honda | S8: City | T8: Sedan | U8: Petrol | V8: Automatic | W8: 1250000 | X8: 2023 | Y8: 4 | Z8: D021 | AA8: =VLOOKUP(Z8,Dealers[],5,FALSE) -> East | AB8: {=VLOOKUP($Z8,Dealers[],{2,7,8,9},FALSE)} -> Bhubaneswar Motors | AC8: 2008 | AD8: 4500 | AE8: 4.3 | AF8: S062 | AG8: =VLOOKUP($AF8,SalesPerson[],2,FALSE) -> Akash Jain | AH8: =_xlfn.XLOOKUP(AG8,Salespersons!$B:$B,Salespersons!$G:$G,,0) -> 5 | AI8: =_xlfn.XLOOKUP(AG8,Salespersons!$B:$B,Salespersons!$I:$I,,0) -> True | AJ8: Silver | AK8: =AL8/W8 -> 0.0496 | AL8: 62000 | AM8: =W8-AL8 -> 1188000 | AN8: =AM8/100000 -> 11.88 | AO8: Loan/Finance | AP8: HDFC Bank | AQ8: Online Website | AR8: No | AS8: {=VLOOKUP($A8,Feedback[],{2,4,5,6,7},FALSE)} -> FB0006 | AT8: 5 | AU8: 10 | AV8: Email | AW8: None
A9: ORD00008 | B9: 45300 | C9: =TEXT(B9,"mmm") -> Jan | D9: =TEXT(B9,"yyyy") -> 2024 | E9: 45319 | F9: Delivered | G9: =IF(E9=0,"",E9-B9) -> 19 | H9: CU0451 | I9: =VLOOKUP($H9,Customers!$A$1:$I$721,2,FALSE) -> Ravi Reddy | J9: =VLOOKUP($H9,Customers!$A$1:$I$721,3,FALSE) -> Male | K9: =VLOOKUP($H9,Customers!$A$1:$I$721,4,FALSE) -> 37 | L9: =VLOOKUP($H9,Customers!$A$1:$I$721,5,FALSE) -> Hyderabad | M9: =VLOOKUP($H9,Customers!$A$1:$I$721,6,FALSE) -> Telangana | N9: =VLOOKUP($H9,Customers!$A$1:$I$721,7,FALSE) -> Retired | O9: =VLOOKUP($H9,Customers!$A$1:$I$721,8,FALSE) -> 520000 | P9: =VLOOKUP($H9,Customers!$A$1:$I$721,9,FALSE) -> Individual | Q9: C004 | R9: {=VLOOKUP($Q9,Cars[],{2,3,4,5,6,7,8,9},FALSE)} -> Maruti Suzuki | S9: Dzire | T9: Sedan | U9: Petrol | V9: Manual | W9: 690000 | X9: 2024 | Y9: 3 | Z9: D018 | AA9: =VLOOKUP(Z9,Dealers[],5,FALSE) -> South | AB9: {=VLOOKUP($Z9,Dealers[],{2,7,8,9},FALSE)} -> Hyderabad Automobiles | AC9: 2019 | AD9: 4500 | AE9: 3.8 | AF9: S053 | AG9: =VLOOKUP($AF9,SalesPerson[],2,FALSE) -> Mohit Patel | AH9: =_xlfn.XLOOKUP(AG9,Salespersons!$B:$B,Salespersons!$G:$G,,0) -> 7 | AI9: =_xlfn.XLOOKUP(AG9,Salespersons!$B:$B,Salespersons!$I:$I,,0) -> True | AJ9: Grey | AK9: =AL9/W9 -> 0 | AL9: 0 | AM9: =W9-AL9 -> 690000 | AN9: =AM9/100000 -> 6.9 | AO9: Loan/Finance | AP9: SBI | AQ9: Referral | AR9: No | AS9: {=VLOOKUP($A9,Feedback[],{2,4,5,6,7},FALSE)} -> FB0007 | AT9: 4 | AU9: 9 | AV9: Phone | AW9: None
A10: ORD00009 | B10: 45300 | C10: =TEXT(B10,"mmm") -> Jan | D10: =TEXT(B10,"yyyy") -> 2024 | E10: 45310 | F10: Delivered | G10: =IF(E10=0,"",E10-B10) -> 10 | H10: CU0252 | I10: =VLOOKUP($H10,Customers!$A$1:$I$721,2,FALSE) -> Mohit Agarwal | J10: =VLOOKUP($H10,Customers!$A$1:$I$721,3,FALSE) -> Male | K10: =VLOOKUP($H10,Customers!$A$1:$I$721,4,FALSE) -> 47 | L10: =VLOOKUP($H10,Customers!$A$1:$I$721,5,FALSE) -> Bhopal | M10: =VLOOKUP($H10,Customers!$A$1:$I$721,6,FALSE) -> Madhya Pradesh | N10: =VLOOKUP($H10,Customers!$A$1:$I$721,7,FALSE) -> Salaried - Government | O10: =VLOOKUP($H10,Customers!$A$1:$I$721,8,FALSE) -> 1480000 | P10: =VLOOKUP($H10,Customers!$A$1:$I$721,9,FALSE) -> Individual | Q10: C004 | R10: {=VLOOKUP($Q10,Cars[],{2,3,4,5,6,7,8,9},FALSE)} -> Maruti Suzuki | S10: Dzire | T10: Sedan | U10: Petrol | V10: Manual | W10: 690000 | X10: 2024 | Y10: 3 | Z10: D025 | AA10: =VLOOKUP(Z10,Dealers[],5,FALSE) -> Central | AB10: {=VLOOKUP($Z10,Dealers[],{2,7,8,9},FALSE)} -> Indore Wheels | AC10: 2019 | AD10: 3000 | AE10: 4.7 | AF10: S074 | AG10: =VLOOKUP($AF10,SalesPerson[],2,FALSE) -> Kunal Shah | AH10: =_xlfn.XLOOKUP(AG10,Salespersons!$B:$B,Salespersons!$G:$G,,0) -> 8 | AI10: =_xlfn.XLOOKUP(AG10,Salespersons!$B:$B,Salespersons!$I:$I,,0) -> True | AJ10: Black | AK10: =AL10/W10 -> 0 | AL10: 0 | AM10: =W10-AL10 -> 690000 | AN10: =AM10/100000 -> 6.9 | AO10: Cash | AP10: N/A | AQ10: Online Website | AR10: No | AS10: {=VLOOKUP($A10,Feedback[],{2,4,5,6,7},FALSE)} -> FB0008 | AT10: 5 | AU10: 10 | AV10: Phone | AW10: None
A11: ORD00010 | B11: 45301 | C11: =TEXT(B11,"mmm") -> Jan | D11: =TEXT(B11,"yyyy") -> 2024 | E11: 45308 | F11: Delivered | G11: =IF(E11=0,"",E11-B11) -> 7 | H11: CU0468 | I11: =VLOOKUP($H11,Customers!$A$1:$I$721,2,FALSE) -> Gaurav Das | J11: =VLOOKUP($H11,Customers!$A$1:$I$721,3,FALSE) -> Male | K11: =VLOOKUP($H11,Customers!$A$1:$I$721,4,FALSE) -> 27 | L11: =VLOOKUP($H11,Customers!$A$1:$I$721,5,FALSE) -> Pune | M11: =VLOOKUP($H11,Customers!$A$1:$I$721,6,FALSE) -> Maharashtra | N11: =VLOOKUP($H11,Customers!$A$1:$I$721,7,FALSE) -> Salaried - Government | O11: =VLOOKUP($H11,Customers!$A$1:$I$721,8,FALSE) -> 750000 | P11: =VLOOKUP($H11,Customers!$A$1:$I$721,9,FALSE) -> Individual | Q11: C005 | R11: {=VLOOKUP($Q11,Cars[],{2,3,4,5,6,7,8,9},FALSE)} -> Maruti Suzuki | S11: Brezza | T11: SUV | U11: Petrol | V11: Automatic | W11: 900000 | X11: 2022 | Y11: 3 | Z11: D011 | AA11: =VLOOKUP(Z11,Dealers[],5,FALSE) -> West | AB11: {=VLOOKUP($Z11,Dealers[],{2,7,8,9},FALSE)} -> Nagpur Motors | AC11: 2019 | AD11: 12000 | AE11: 4.6 | AF11: S034 | AG11: =VLOOKUP($AF11,SalesPerson[],2,FALSE) -> Arjun Reddy | AH11: =_xlfn.XLOOKUP(AG11,Salespersons!$B:$B,Salespersons!$G:$G,,0) -> 5 | AI11: =_xlfn.XLOOKUP(AG11,Salespersons!$B:$B,Salespersons!$I:$I,,0) -> True | AJ11: White | AK11: =AL11/W11 -> 0.03 | AL11: 27000 | AM11: =W11-AL11 -> 873000 | AN11: =AM11/100000 -> 8.73 | AO11: Cash | AP11: N/A | AQ11: Online Website | AR11: Yes | AS11: {=VLOOKUP($A11,Feedback[],{2,4,5,6,7},FALSE)} -> FB0009 | AT11: 4 | AU11: 9 | AV11: Email | AW11: None
A12: ORD00011 | B12: 45303 | C12: =TEXT(B12,"mmm") -> Jan | D12: =TEXT(B12,"yyyy") -> 2024 | E12: 45318 | F12: Delivered | G12: =IF(E12=0,"",E12-B12) -> 15 | H12: CU0197 | I12: =VLOOKUP($H12,Customers!$A$1:$I$721,2,FALSE) -> Aman Mehta | J12: =VLOOKUP($H12,Customers!$A$1:$I$721,3,FALSE) -> Male | K12: =VLOOKUP($H12,Customers!$A$1:$I$721,4,FALSE) -> 52 | L12: =VLOOKUP($H12,Customers!$A$1:$I$721,5,FALSE) -> Gurugram | M12: =VLOOKUP($H12,Customers!$A$1:$I$721,6,FALSE) -> Haryana | N12: =VLOOKUP($H12,Customers!$A$1:$I$721,7,FALSE) -> Salaried - Private | O12: =VLOOKUP($H12,Customers!$A$1:$I$721,8,FALSE) -> 1180000 | P12: =VLOOKUP($H12,Customers!$A$1:$I$721,9,FALSE) -> Individual | Q12: C014 | R12: {=VLOOKUP($Q12,Cars[],{2,3,4,5,6,7,8,9},FALSE)} -> Tata | S12: Tiago | T12: Hatchback | U12: Petrol | V12: Manual | W12: 570000 | X12: 2022 | Y12: 3 | Z12: D003 | AA12: =VLOOKUP(Z12,Dealers[],5,FALSE) -> North | AB12: {=VLOOKUP($Z12,Dealers[],{2,7,8,9},FALSE)} -> Panipat Motors | AC12: 2012 | AD12: 10000 | AE12: 4.2 | AF12: S011 | AG12: =VLOOKUP($AF12,SalesPerson[],2,FALSE) -> Yash Bose | AH12: =_xlfn.XLOOKUP(AG12,Salespersons!$B:$B,Salespersons!$G:$G,,0) -> 7 | AI12: =_xlfn.XLOOKUP(AG12,Salespersons!$B:$B,Salespersons!$I:$I,,0) -> True | AJ12: Red | AK12: =AL12/W12 -> 0.019298246 | AL12: 11000 | AM12: =W12-AL12 -> 559000 | AN12: =AM12/100000 -> 5.59 | AO12: Cash | AP12: N/A | AQ12: Referral | AR12: Yes | AS12: {=VLOOKUP($A12,Feedback[],{2,4,5,6,7},FALSE)} -> FB0010 | AT12: 4 | AU12: 8 | AV12: Phone | AW12: None
A13: ORD00012 | B13: 45303 | C13: =TEXT(B13,"mmm") -> Jan | D13: =TEXT(B13,"yyyy") -> 2024 | E13: 45319 | F13: Delivered | G13: =IF(E13=0,"",E13-B13) -> 16 | H13: CU0336 | I13: =VLOOKUP($H13,Customers!$A$1:$I$721,2,FALSE) -> Kunal Bansal | J13: =VLOOKUP($H13,Customers!$A$1:$I$721,3,FALSE) -> Male | K13: =VLOOKUP($H13,Customers!$A$1:$I$721,4,FALSE) -> 57 | L13: =VLOOKUP($H13,Customers!$A$1:$I$721,5,FALSE) -> Pune | M13: =VLOOKUP($H13,Customers!$A$1:$I$721,6,FALSE) -> Maharashtra | N13: =VLOOKUP($H13,Customers!$A$1:$I$721,7,FALSE) -> Business Owner | O13: =VLOOKUP($H13,Customers!$A$1:$I$721,8,FALSE) -> 3160000 | P13: =VLOOKUP($H13,Customers!$A$1:$I$721,9,FALSE) -> Individual | Q13: C005 | R13: {=VLOOKUP($Q13,Cars[],{2,3,4,5,6,7,8,9},FALSE)} -> Maruti Suzuki | S13: Brezza | T13: SUV | U13: Petrol | V13: Automatic | W13: 900000 | X13: 2022 | Y13: 3 | Z13: D010 | AA13: =VLOOKUP(Z13,Dealers[],5,FALSE) -> West | AB13: {=VLOOKUP($Z13,Dealers[],{2,7,8,9},FALSE)} -> Pune Autoplex | AC13: 2014 | AD13: 3000 | AE13: 4.6 | AF13: S031 | AG13: =VLOOKUP($AF13,SalesPerson[],2,FALSE) -> Ankit Verma | AH13: =_xlfn.XLOOKUP(AG13,Salespersons!$B:$B,Salespersons!$G:$G,,0) -> 4 | AI13: =_xlfn.XLOOKUP(AG13,Salespersons!$B:$B,Salespersons!$I:$I,,0) -> True | AJ13: Grey | AK13: =AL13/W13 -> 0.045555556 | AL13: 41000 | AM13: =W13-AL13 -> 859000 | AN13: =AM13/100000 -> 8.59 | AO13: Cash | AP13: N/A | AQ13: Auto Expo/Event | AR13: No | AS13: No Feedback | AT13: No Feedback | AU13: No Feedback | AV13: No Feedback | AW13: No Feedback
A14: ORD00013 | B14: 45308 | C14: =TEXT(B14,"mmm") -> Jan | D14: =TEXT(B14,"yyyy") -> 2024 | E14: 45334 | F14: Delivered | G14: =IF(E14=0,"",E14-B14) -> 26 | H14: CU0680 | I14: =VLOOKUP($H14,Customers!$A$1:$I$721,2,FALSE) -> Ankit Gupta | J14: =VLOOKUP($H14,Customers!$A$1:$I$721,3,FALSE) -> Male | K14: =VLOOKUP($H14,Customers!$A$1:$I$721,4,FALSE) -> 26 | L14: =VLOOKUP($H14,Customers!$A$1:$I$721,5,FALSE) -> Ludhiana | M14: =VLOOKUP($H14,Customers!$A$1:$I$721,6,FALSE) -> Punjab | N14: =VLOOKUP($H14,Customers!$A$1:$I$721,7,FALSE) -> Farmer | O14: =VLOOKUP($H14,Customers!$A$1:$I$721,8,FALSE) -> 550000 | P14: =VLOOKUP($H14,Customers!$A$1:$I$721,9,FALSE) -> Individual | Q14: C015 | R14: {=VLOOKUP($Q14,Cars[],{2,3,4,5,6,7,8,9},FALSE)} -> Tata | S14: Punch | T14: SUV | U14: Petrol | V14: Manual | W14: 650000 | X14: 2021 | Y14: 3 | Z14: D005 | AA14: =VLOOKUP(Z14,Dealers[],5,FALSE) -> North | AB14: {=VLOOKUP($Z14,Dealers[],{2,7,8,9},FALSE)} -> Ludhiana Wheels | AC14: 2010 | AD14: 12000 | AE14: 4 | AF14: S015 | AG14: =VLOOKUP($AF14,SalesPerson[],2,FALSE) -> Akash Verma | AH14: =_xlfn.XLOOKUP(AG14,Salespersons!$B:$B,Salespersons!$G:$G,,0) -> 8 | AI14: =_xlfn.XLOOKUP(AG14,Salespersons!$B:$B,Salespersons!$I:$I,,0) -> True | AJ14: Silver | AK14: =AL14/W14 -> 0.018461538 | AL14: 12000 | AM14: =W14-AL14 -> 638000 | AN14: =AM14/100000 -> 6.38 | AO14: Cash | AP14: N/A | AQ14: Social Media | AR14: No | AS14: No Feedback | AT14: No Feedback | AU14: No Feedback | AV14: No Feedback | AW14: No Feedback
A15: ORD00014 | B15: 45309 | C15: =TEXT(B15,"mmm") -> Jan | D15: =TEXT(B15,"yyyy") -> 2024 | E15: 45325 | F15: Delivered | G15: =IF(E15=0,"",E15-B15) -> 16 | H15: CU0507 | I15: =VLOOKUP($H15,Customers!$A$1:$I$721,2,FALSE) -> Ashok Das | J15: =VLOOKUP($H15,Customers!$A$1:$I$721,3,FALSE) -> Male | K15: =VLOOKUP($H15,Customers!$A$1:$I$721,4,FALSE) -> 27 | L15: =VLOOKUP($H15,Customers!$A$1:$I$721,5,FALSE) -> Indore | M15: =VLOOKUP($H15,Customers!$A$1:$I$721,6,FALSE) -> Madhya Pradesh | N15: =VLOOKUP($H15,Customers!$A$1:$I$721,7,FALSE) -> Salaried - Private | O15: =VLOOKUP($H15,Customers!$A$1:$I$721,8,FALSE) -> 880000 | P15: =VLOOKUP($H15,Customers!$A$1:$I$721,9,FALSE) -> Individual | Q15: C012 | R15: {=VLOOKUP($Q15,Cars[],{2,3,4,5,6,7,8,9},FALSE)} -> Hyundai | S15: Verna | T15: Sedan | U15: Petrol | V15: Automatic | W15: 1100000 | X15: 2023 | Y15: 2 | Z15: D024 | AA15: =VLOOKUP(Z15,Dealers[],5,FALSE) -> Central | AB15: {=VLOOKUP($Z15,Dealers[],{2,7,8,9},FALSE)} -> Bhopal Autoplex | AC15: 2013 | AD15: 12000 | AE15: 3.9 | AF15: S071 | AG15: =VLOOKUP($AF15,SalesPerson[],2,FALSE) -> Imran Verma | AH15: =_xlfn.XLOOKUP(AG15,Salespersons!$B:$B,Salespersons!$G:$G,,0) -> 5 | AI15: =_xlfn.XLOOKUP(AG15,Salespersons!$B:$B,Salespersons!$I:$I,,0) -> True | AJ15: Black | AK15: =AL15/W15 -> 0 | AL15: 0 | AM15: =W15-AL15 -> 1100000 | AN15: =AM15/100000 -> 11 | AO15: Exchange + Loan | AP15: Tata Capital | AQ15: Social Media | AR15: No | AS15: {=VLOOKUP($A15,Feedback[],{2,4,5,6,7},FALSE)} -> FB0011 | AT15: 3 | AU15: 6 | AV15: Online Survey | AW15: After-Sales Support
A16: ORD00015 | B16: 45312 | C16: =TEXT(B16,"mmm") -> Jan | D16: =TEXT(B16,"yyyy") -> 2024 | E16: 45329 | F16: Delivered | G16: =IF(E16=0,"",E16-B16) -> 17 | H16: CU0161 | I16: =VLOOKUP($H16,Customers!$A$1:$I$721,2,FALSE) -> Imran Khanna | J16: =VLOOKUP($H16,Customers!$A$1:$I$721,3,FALSE) -> Male | K16: =VLOOKUP($H16,Customers!$A$1:$I$721,4,FALSE) -> 25 | L16: =VLOOKUP($H16,Customers!$A$1:$I$721,5,FALSE) -> Pune | M16: =VLOOKUP($H16,Customers!$A$1:$I$721,6,FALSE) -> Maharashtra | N16: =VLOOKUP($H16,Customers!$A$1:$I$721,7,FALSE) -> Salaried - Private | O16: =VLOOKUP($H16,Customers!$A$1:$I$721,8,FALSE) -> 960000 | P16: =VLOOKUP($H16,Customers!$A$1:$I$721,9,FALSE) -> Individual | Q16: C034 | R16: {=VLOOKUP($Q16,Cars[],{2,3,4,5,6,7,8,9},FALSE)} -> Volkswagen | S16: Virtus | T16: Sedan | U16: Petrol | V16: Automatic | W16: 1350000 | X16: 2022 | Y16: 3 | Z16: D011 | AA16: =VLOOKUP(Z16,Dealers[],5,FALSE) -> West | AB16: {=VLOOKUP($Z16,Dealers[],{2,7,8,9},FALSE)} -> Nagpur Motors | AC16: 2019 | AD16: 12000 | AE16: 4.6 | AF16: S034 | AG16: =VLOOKUP($AF16,SalesPerson[],2,FALSE) -> Arjun Reddy | AH16: =_xlfn.XLOOKUP(AG16,Salespersons!$B:$B,Salespersons!$G:$G,,0) -> 5 | AI16: =_xlfn.XLOOKUP(AG16,Salespersons!$B:$B,Salespersons!$I:$I,,0) -> True | AJ16: Silver | AK16: =AL16/W16 -> 0 | AL16: 0 | AM16: =W16-AL16 -> 1350000 | AN16: =AM16/100000 -> 13.5 | AO16: Loan/Finance | AP16: Axis Bank | AQ16: Social Media | AR16: No | AS16: {=VLOOKUP($A16,Feedback[],{2,4,5,6,7},FALSE)} -> FB0012 | AT16: 5 | AU16: 10 | AV16: Phone | AW16: None
A17: ORD00016 | B17: 45314 | C17: =TEXT(B17,"mmm") -> Jan | D17: =TEXT(B17,"yyyy") -> 2024 | E17: 45328 | F17: Delivered | G17: =IF(E17=0,"",E17-B17) -> 14 | H17: CU0637 | I17: =VLOOKUP($H17,Customers!$A$1:$I$721,2,FALSE) -> Kunal Singh | J17: =VLOOKUP($H17,Customers!$A$1:$I$721,3,FALSE) -> Male | K17: =VLOOKUP($H17,Customers!$A$1:$I$721,4,FALSE) -> 45 | L17: =VLOOKUP($H17,Customers!$A$1:$I$721,5,FALSE) -> Bengaluru | M17: =VLOOKUP($H17,Customers!$A$1:$I$721,6,FALSE) -> Karnataka | N17: =VLOOKUP($H17,Customers!$A$1:$I$721,7,FALSE) -> Student/Other | O17: =VLOOKUP($H17,Customers!$A$1:$I$721,8,FALSE) -> 480000 | P17: =VLOOKUP($H17,Customers!$A$1:$I$721,9,FALSE) -> Individual | Q17: C006 | R17: {=VLOOKUP($Q17,Cars[],{2,3,4,5,6,7,8,9},FALSE)} -> Maruti Suzuki | S17: Ertiga | T17: MPV | U17: CNG | V17: Manual | W17: 900000 | X17: 2022 | Y17: 3 | Z17: D015 | AA17: =VLOOKUP(Z17,Dealers[],5,FALSE) -> South | AB17: {=VLOOKUP($Z17,Dealers[],{2,7,8,9},FALSE)} -> Mysuru Auto Hub | AC17: 2006 | AD17: 4500 | AE17: 4.6 | AF17: S046 | AG17: =VLOOKUP($AF17,SalesPerson[],2,FALSE) -> Tanvi Reddy | AH17: =_xlfn.XLOOKUP(AG17,Salespersons!$B:$B,Salespersons!$G:$G,,0) -> 4 | AI17: =_xlfn.XLOOKUP(AG17,Salespersons!$B:$B,Salespersons!$I:$I,,0) -> True | AJ17: Black | AK17: =AL17/W17 -> 0.01 | AL17: 9000 | AM17: =W17-AL17 -> 891000 | AN17: =AM17/100000 -> 8.91 | AO17: Loan/Finance | AP17: ICICI Bank | AQ17: Referral | AR17: No | AS17: {=VLOOKUP($A17,Feedback[],{2,4,5,6,7},FALSE)} -> FB0013 | AT17: 5 | AU17: 9 | AV17: Dealer Visit | AW17: None
A18: ORD00017 | B18: 45314 | C18: =TEXT(B18,"mmm") -> Jan | D18: =TEXT(B18,"yyyy") -> 2024 | E18: 45329 | F18: Delivered | G18: =IF(E18=0,"",E18-B18) -> 15 | H18: CU0078 | I18: =VLOOKUP($H18,Customers!$A$1:$I$721,2,FALSE) -> Karan Chauhan | J18: =VLOOKUP($H18,Customers!$A$1:$I$721,3,FALSE) -> Male | K18: =VLOOKUP($H18,Customers!$A$1:$I$721,4,FALSE) -> 38 | L18: =VLOOKUP($H18,Customers!$A$1:$I$721,5,FALSE) -> Delhi | M18: =VLOOKUP($H18,Customers!$A$1:$I$721,6,FALSE) -> Delhi | N18: =VLOOKUP($H18,Customers!$A$1:$I$721,7,FALSE) -> Business Owner | O18: =VLOOKUP($H18,Customers!$A$1:$I$721,8,FALSE) -> 1260000 | P18: =VLOOKUP($H18,Customers!$A$1:$I$721,9,FALSE) -> Individual | Q18: C008 | R18: {=VLOOKUP($Q18,Cars[],{2,3,4,5,6,7,8,9},FALSE)} -> Hyundai | S18: i10 Nios | T18: Hatchback | U18: Petrol | V18: Manual | W18: 600000 | X18: 2023 | Y18: 3 | Z18: D001 | AA18: =VLOOKUP(Z18,Dealers[],5,FALSE) -> North | AB18: {=VLOOKUP($Z18,Dealers[],{2,7,8,9},FALSE)} -> Delhi Autoplex | AC18: 2013 | AD18: 4500 | AE18: 3.7 | AF18: S003 | AG18: =VLOOKUP($AF18,SalesPerson[],2,FALSE) -> Karan Verma | AH18: =_xlfn.XLOOKUP(AG18,Salespersons!$B:$B,Salespersons!$G:$G,,0) -> 5 | AI18: =_xlfn.XLOOKUP(AG18,Salespersons!$B:$B,Salespersons!$I:$I,,0) -> True | AJ18: Black | AK18: =AL18/W18 -> 0 | AL18: 0 | AM18: =W18-AL18 -> 600000 | AN18: =AM18/100000 -> 6 | AO18: Loan/Finance | AP18: ICICI Bank | AQ18: Corporate Tie-up | AR18: No | AS18: No Feedback | AT18: No Feedback | AU18: No Feedback | AV18: No Feedback | AW18: No Feedback
A19: ORD00018 | B19: 45314 | C19: =TEXT(B19,"mmm") -> Jan | D19: =TEXT(B19,"yyyy") -> 2024 | F19: Cancelled | G19: =IF(E19=0,"",E19-B19) | H19: CU0257 | I19: =VLOOKUP($H19,Customers!$A$1:$I$721,2,FALSE) -> Arjun Mehta | J19: =VLOOKUP($H19,Customers!$A$1:$I$721,3,FALSE) -> Male | K19: =VLOOKUP($H19,Customers!$A$1:$I$721,4,FALSE) -> 41 | L19: =VLOOKUP($H19,Customers!$A$1:$I$721,5,FALSE) -> Lucknow | M19: =VLOOKUP($H19,Customers!$A$1:$I$721,6,FALSE) -> Uttar Pradesh | N19: =VLOOKUP($H19,Customers!$A$1:$I$721,7,FALSE) -> Engineer | O19: =VLOOKUP($H19,Customers!$A$1:$I$721,8,FALSE) -> 1510000 | P19: =VLOOKUP($H19,Customers!$A$1:$I$721,9,FALSE) -> Individual | Q19: C006 | R19: {=VLOOKUP($Q19,Cars[],{2,3,4,5,6,7,8,9},FALSE)} -> Maruti Suzuki | S19: Ertiga | T19: MPV | U19: CNG | V19: Manual | W19: 900000 | X19: 2022 | Y19: 3 | Z19: D008 | AA19: =VLOOKUP(Z19,Dealers[],5,FALSE) -> North | AB19: {=VLOOKUP($Z19,Dealers[],{2,7,8,9},FALSE)} -> Noida Car World | AC19: 2007 | AD19: 10000 | AE19: 3.8 | AF19: S023 | AG19: =VLOOKUP($AF19,SalesPerson[],2,FALSE) -> Kunal Jain | AH19: =_xlfn.XLOOKUP(AG19,Salespersons!$B:$B,Salespersons!$G:$G,,0) -> 8 | AI19: =_xlfn.XLOOKUP(AG19,Salespersons!$B:$B,Salespersons!$I:$I,,0) -> True | AJ19: Grey | AK19: =AL19/W19 -> 0.036666667 | AL19: 33000 | AM19: =W19-AL19 -> 867000 | AN19: =AM19/100000 -> 8.67 | AO19: Cash | AP19: N/A | AQ19: Corporate Tie-up | AR19: No | AS19: No Feedback | AT19: No Feedback | AU19: No Feedback | AV19: No Feedback | AW19: No Feedback
A20: ORD00019 | B20: 45315 | C20: =TEXT(B20,"mmm") -> Jan | D20: =TEXT(B20,"yyyy") -> 2024 | E20: 45318 | F20: Delivered | G20: =IF(E20=0,"",E20-B20) -> 3 | H20: CU0557 | I20: =VLOOKUP($H20,Customers!$A$1:$I$721,2,FALSE) -> Mahesh Malhotra | J20: =VLOOKUP($H20,Customers!$A$1:$I$721,3,FALSE) -> Male | K20: =VLOOKUP($H20,Customers!$A$1:$I$721,4,FALSE) -> 46 | L20: =VLOOKUP($H20,Customers!$A$1:$I$721,5,FALSE) -> Panipat | M20: =VLOOKUP($H20,Customers!$A$1:$I$721,6,FALSE) -> Haryana | N20: =VLOOKUP($H20,Customers!$A$1:$I$721,7,FALSE) -> Salaried - Private | O20: =VLOOKUP($H20,Customers!$A$1:$I$721,8,FALSE) -> 1690000 | P20: =VLOOKUP($H20,Customers!$A$1:$I$721,9,FALSE) -> Individual | Q20: C032 | R20: {=VLOOKUP($Q20,Cars[],{2,3,4,5,6,7,8,9},FALSE)} -> Kia | S20: Carens | T20: MPV | U20: Diesel | V20: Manual | W20: 1200000 | X20: 2022 | Y20: 3 | Z20: D003 | AA20: =VLOOKUP(Z20,Dealers[],5,FALSE) -> North | AB20: {=VLOOKUP($Z20,Dealers[],{2,7,8,9},FALSE)} -> Panipat Motors | AC20: 2012 | AD20: 10000 | AE20: 4.2 | AF20: S010 | AG20: =VLOOKUP($AF20,SalesPerson[],2,FALSE) -> Rahul Rao | AH20: =_xlfn.XLOOKUP(AG20,Salespersons!$B:$B,Salespersons!$G:$G,,0) -> 5 | AI20: =_xlfn.XLOOKUP(AG20,Salespersons!$B:$B,Salespersons!$I:$I,,0) -> True | AJ20: Silver | AK20: =AL20/W20 -> 0.043333333 | AL20: 52000 | AM20: =W20-AL20 -> 1148000 | AN20: =AM20/100000 -> 11.48 | AO20: Exchange + Loan | AP20: Axis Bank | AQ20: Test Drive Campaign | AR20: Yes | AS20: {=VLOOKUP($A20,Feedback[],{2,4,5,6,7},FALSE)} -> FB0014 | AT20: 5 | AU20: 10 | AV20: Email | AW20: None
A21: ORD00020 | B21: 45316 | C21: =TEXT(B21,"mmm") -> Jan | D21: =TEXT(B21,"yyyy") -> 2024 | E21: 45348 | F21: Delivered | G21: =IF(E21=0,"",E21-B21) -> 32 | H21: CU0408 | I21: =VLOOKUP($H21,Customers!$A$1:$I$721,2,FALSE) -> Gaurav Mehta | J21: =VLOOKUP($H21,Customers!$A$1:$I$721,3,FALSE) -> Male | K21: =VLOOKUP($H21,Customers!$A$1:$I$721,4,FALSE) -> 21 | L21: =VLOOKUP($H21,Customers!$A$1:$I$721,5,FALSE) -> Ludhiana | M21: =VLOOKUP($H21,Customers!$A$1:$I$721,6,FALSE) -> Punjab | N21: =VLOOKUP($H21,Customers!$A$1:$I$721,7,FALSE) -> Teacher | O21: =VLOOKUP($H21,Customers!$A$1:$I$721,8,FALSE) -> 470000 | P21: =VLOOKUP($H21,Customers!$A$1:$I$721,9,FALSE) -> Individual | Q21: C004 | R21: {=VLOOKUP($Q21,Cars[],{2,3,4,5,6,7,8,9},FALSE)} -> Maruti Suzuki | S21: Dzire | T21: Sedan | U21: Petrol | V21: Manual | W21: 690000 | X21: 2024 | Y21: 3 | Z21: D005 | AA21: =VLOOKUP(Z21,Dealers[],5,FALSE) -> North | AB21: {=VLOOKUP($Z21,Dealers[],{2,7,8,9},FALSE)} -> Ludhiana Wheels | AC21: 2010 | AD21: 12000 | AE21: 4 | AF21: S015 | AG21: =VLOOKUP($AF21,SalesPerson[],2,FALSE) -> Akash Verma | AH21: =_xlfn.XLOOKUP(AG21,Salespersons!$B:$B,Salespersons!$G:$G,,0) -> 8 | AI21: =_xlfn.XLOOKUP(AG21,Salespersons!$B:$B,Salespersons!$I:$I,,0) -> True | AJ21: Black | AK21: =AL21/W21 -> 0 | AL21: 0 | AM21: =W21-AL21 -> 690000 | AN21: =AM21/100000 -> 6.9 | AO21: Cash | AP21: N/A | AQ21: Walk-in | AR21: No | AS21: {=VLOOKUP($A21,Feedback[],{2,4,5,6,7},FALSE)} -> FB0015 | AT21: 4 | AU21: 7 | AV21: Phone | AW21: None
A22: ORD00021 | B22: 45317 | C22: =TEXT(B22,"mmm") -> Jan | D22: =TEXT(B22,"yyyy") -> 2024 | E22: 45328 | F22: Delivered | G22: =IF(E22=0,"",E22-B22) -> 11 | H22: CU0193 | I22: =VLOOKUP($H22,Customers!$A$1:$I$721,2,FALSE) -> Sneha Gupta | J22: =VLOOKUP($H22,Customers!$A$1:$I$721,3,FALSE) -> Female | K22: =VLOOKUP($H22,Customers!$A$1:$I$721,4,FALSE) -> 29 | L22: =VLOOKUP($H22,Customers!$A$1:$I$721,5,FALSE) -> Chandigarh | M22: =VLOOKUP($H22,Customers!$A$1:$I$721,6,FALSE) -> Chandigarh | N22: =VLOOKUP($H22,Customers!$A$1:$I$721,7,FALSE) -> Self-Employed Professional | O22: =VLOOKUP($H22,Customers!$A$1:$I$721,8,FALSE) -> 1390000 | P22: =VLOOKUP($H22,Customers!$A$1:$I$721,9,FALSE) -> Individual | Q22: C011 | R22: {=VLOOKUP($Q22,Cars[],{2,3,4,5,6,7,8,9},FALSE)} -> Hyundai | S22: Creta | T22: SUV | U22: Diesel | V22: Automatic | W22: 1250000 | X22: 2024 | Y22: 4 | Z22: D014 | AA22: =VLOOKUP(Z22,Dealers[],5,FALSE) -> South | AB22: {=VLOOKUP($Z22,Dealers[],{2,7,8,9},FALSE)} -> Bengaluru Auto Hub | AC22: 2013 | AD22: 12000 | AE22: 4.4 | AF22: S042 | AG22: =VLOOKUP($AF22,SalesPerson[],2,FALSE) -> Yash Sharma | AH22: =_xlfn.XLOOKUP(AG22,Salespersons!$B:$B,Salespersons!$G:$G,,0) -> 5 | AI22: =_xlfn.XLOOKUP(AG22,Salespersons!$B:$B,Salespersons!$I:$I,,0) -> True | AJ22: Silver | AK22: =AL22/W22 -> 0.0176 | AL22: 22000 | AM22: =W22-AL22 -> 1228000 | AN22: =AM22/100000 -> 12.28 | AO22: Cash | AP22: N/A | AQ22: Online Website | AR22: No | AS22: {=VLOOKUP($A22,Feedback[],{2,4,5,6,7},FALSE)} -> FB0016 | AT22: 5 | AU22: 10 | AV22: Email | AW22: None
A23: ORD00022 | B23: 45317 | C23: =TEXT(B23,"mmm") -> Jan | D23: =TEXT(B23,"yyyy") -> 2024 | E23: 45339 | F23: Delivered | G23: =IF(E23=0,"",E23-B23) -> 22 | H23: CU0010 | I23: =VLOOKUP($H23,Customers!$A$1:$I$721,2,FALSE) -> Nisha Mishra | J23: =VLOOKUP($H23,Customers!$A$1:$I$721,3,FALSE) -> Female | K23: =VLOOKUP($H23,Customers!$A$1:$I$721,4,FALSE) -> 21 | L23: =VLOOKUP($H23,Customers!$A$1:$I$721,5,FALSE) -> Pune | M23: =VLOOKUP($H23,Customers!$A$1:$I$721,6,FALSE) -> Maharashtra | N23: =VLOOKUP($H23,Customers!$A$1:$I$721,7,FALSE) -> Student/Other | O23: =VLOOKUP($H23,Customers!$A$1:$I$721,8,FALSE) -> 590000 | P23: =VLOOKUP($H23,Customers!$A$1:$I$721,9,FALSE) -> Individual | Q23: C012 | R23: {=VLOOKUP($Q23,Cars[],{2,3,4,5,6,7,8,9},FALSE)} -> Hyundai | S23: Verna | T23: Sedan | U23: Petrol | V23: Automatic | W23: 1100000 | X23: 2023 | Y23: 2 | Z23: D010 | AA23: =VLOOKUP(Z23,Dealers[],5,FALSE) -> West | AB23: {=VLOOKUP($Z23,Dealers[],{2,7,8,9},FALSE)} -> Pune Autoplex | AC23: 2014 | AD23: 3000 | AE23: 4.6 | AF23: S032 | AG23: =VLOOKUP($AF23,SalesPerson[],2,FALSE) -> Nitin Pillai | AH23: =_xlfn.XLOOKUP(AG23,Salespersons!$B:$B,Salespersons!$G:$G,,0) -> 6 | AI23: =_xlfn.XLOOKUP(AG23,Salespersons!$B:$B,Salespersons!$I:$I,,0) -> True | AJ23: Black | AK23: =AL23/W23 -> 0 | AL23: 0 | AM23: =W23-AL23 -> 1100000 | AN23: =AM23/100000 -> 11 | AO23: Exchange + Loan | AP23: Tata Capital | AQ23: Walk-in | AR23: No | AS23: No Feedback | AT23: No Feedback | AU23: No Feedback | AV23: No Feedback | AW23: No Feedback
A24: ORD00023 | B24: 45320 | C24: =TEXT(B24,"mmm") -> Jan | D24: =TEXT(B24,"yyyy") -> 2024 | E24: 45335 | F24: Delivered | G24: =IF(E24=0,"",E24-B24) -> 15 | H24: CU0033 | I24: =VLOOKUP($H24,Customers!$A$1:$I$721,2,FALSE) -> Suresh Nair | J24: =VLOOKUP($H24,Customers!$A$1:$I$721,3,FALSE) -> Male | K24: =VLOOKUP($H24,Customers!$A$1:$I$721,4,FALSE) -> 38 | L24: =VLOOKUP($H24,Customers!$A$1:$I$721,5,FALSE) -> Guwahati | M24: =VLOOKUP($H24,Customers!$A$1:$I$721,6,FALSE) -> Assam | N24: =VLOOKUP($H24,Customers!$A$1:$I$721,7,FALSE) -> Teacher | O24: =VLOOKUP($H24,Customers!$A$1:$I$721,8,FALSE) -> 620000 | P24: =VLOOKUP($H24,Customers!$A$1:$I$721,9,FALSE) -> Individual | Q24: C033 | R24: {=VLOOKUP($Q24,Cars[],{2,3,4,5,6,7,8,9},FALSE)} -> Skoda | S24: Slavia | T24: Sedan | U24: Petrol | V24: Automatic | W24: 1300000 | X24: 2022 | Y24: 3 | Z24: D023 | AA24: =VLOOKUP(Z24,Dealers[],5,FALSE) -> East | AB24: {=VLOOKUP($Z24,Dealers[],{2,7,8,9},FALSE)} -> Guwahati Automobiles | AC24: 2005 | AD24: 12000 | AE24: 4.4 | AF24: S070 | AG24: =VLOOKUP($AF24,SalesPerson[],2,FALSE) -> Tarun Mehta | AH24: =_xlfn.XLOOKUP(AG24,Salespersons!$B:$B,Salespersons!$G:$G,,0) -> 4 | AI24: =_xlfn.XLOOKUP(AG24,Salespersons!$B:$B,Salespersons!$I:$I,,0) -> True | AJ24: Silver | AK24: =AL24/W24 -> 0.016923077 | AL24: 22000 | AM24: =W24-AL24 -> 1278000 | AN24: =AM24/100000 -> 12.78 | AO24: Exchange + Loan | AP24: HDFC Bank | AQ24: Referral | AR24: No | AS24: {=VLOOKUP($A24,Feedback[],{2,4,5,6,7},FALSE)} -> FB0017 | AT24: 4 | AU24: 7 | AV24: Email | AW24: None
A25: ORD00024 | B25: 45320 | C25: =TEXT(B25,"mmm") -> Jan | D25: =TEXT(B25,"yyyy") -> 2024 | E25: 45354 | F25: Delivered | G25: =IF(E25=0,"",E25-B25) -> 34 | H25: CU0463 | I25: =VLOOKUP($H25,Customers!$A$1:$I$721,2,FALSE) -> Nitin Gupta | J25: =VLOOKUP($H25,Customers!$A$1:$I$721,3,FALSE) -> Male | K25: =VLOOKUP($H25,Customers!$A$1:$I$721,4,FALSE) -> 49 | L25: =VLOOKUP($H25,Customers!$A$1:$I$721,5,FALSE) -> Panipat | M25: =VLOOKUP($H25,Customers!$A$1:$I$721,6,FALSE) -> Haryana | N25: =VLOOKUP($H25,Customers!$A$1:$I$721,7,FALSE) -> Salaried - Private | O25: =VLOOKUP($H25,Customers!$A$1:$I$721,8,FALSE) -> 1440000 | P25: =VLOOKUP($H25,Customers!$A$1:$I$721,9,FALSE) -> Individual | Q25: C016 | R25: {=VLOOKUP($Q25,Cars[],{2,3,4,5,6,7,8,9},FALSE)} -> Tata | S25: Nexon | T25: SUV | U25: Diesel | V25: Manual | W25: 950000 | X25: 2023 | Y25: 3 | Z25: D002 | AA25: =VLOOKUP(Z25,Dealers[],5,FALSE) -> North | AB25: {=VLOOKUP($Z25,Dealers[],{2,7,8,9},FALSE)} -> Gurugram Autoplex | AC25: 2007 | AD25: 10000 | AE25: 4 | AF25: S005 | AG25: =VLOOKUP($AF25,SalesPerson[],2,FALSE) -> Mohit Bose | AH25: =_xlfn.XLOOKUP(AG25,Salespersons!$B:$B,Salespersons!$G:$G,,0) -> 4 | AI25: =_xlfn.XLOOKUP(AG25,Salespersons!$B:$B,Salespersons!$I:$I,,0) -> True | AJ25: White | AK25: =AL25/W25 -> 0.036842105 | AL25: 35000 | AM25: =W25-AL25 -> 915000 | AN25: =AM25/100000 -> 9.15 | AO25: Loan/Finance | AP25: Tata Capital | AQ25: Online Website | AR25: Yes | AS25: No Feedback | AT25: No Feedback | AU25: No Feedback | AV25: No Feedback | AW25: No Feedback
A26: ORD00025 | B26: 45320 | C26: =TEXT(B26,"mmm") -> Jan | D26: =TEXT(B26,"yyyy") -> 2024 | E26: 45349 | F26: Delivered | G26: =IF(E26=0,"",E26-B26) -> 29 | H26: CU0396 | I26: =VLOOKUP($H26,Customers!$A$1:$I$721,2,FALSE) -> Kamal Khanna | J26: =VLOOKUP($H26,Customers!$A$1:$I$721,3,FALSE) -> Male | K26: =VLOOKUP($H26,Customers!$A$1:$I$721,4,FALSE) -> 24 | L26: =VLOOKUP($H26,Customers!$A$1:$I$721,5,FALSE) -> Delhi | M26: =VLOOKUP($H26,Customers!$A$1:$I$721,6,FALSE) -> Delhi | N26: =VLOOKUP($H26,Customers!$A$1:$I$721,7,FALSE) -> Salaried - Government | O26: =VLOOKUP($H26,Customers!$A$1:$I$721,8,FALSE) -> 600000 | P26: =VLOOKUP($H26,Customers!$A$1:$I$721,9,FALSE) -> Individual | Q26: C006 | R26: {=VLOOKUP($Q26,Cars[],{2,3,4,5,6,7,8,9},FALSE)} -> Maruti Suzuki | S26: Ertiga | T26: MPV | U26: CNG | V26: Manual | W26: 900000 | X26: 2022 | Y26: 3 | Z26: D001 | AA26: =VLOOKUP(Z26,Dealers[],5,FALSE) -> North | AB26: {=VLOOKUP($Z26,Dealers[],{2,7,8,9},FALSE)} -> Delhi Autoplex | AC26: 2013 | AD26: 4500 | AE26: 3.7 | AF26: S004 | AG26: =VLOOKUP($AF26,SalesPerson[],2,FALSE) -> Lokesh Nair | AH26: =_xlfn.XLOOKUP(AG26,Salespersons!$B:$B,Salespersons!$G:$G,,0) -> 8 | AI26: =_xlfn.XLOOKUP(AG26,Salespersons!$B:$B,Salespersons!$I:$I,,0) -> False | AJ26: Black | AK26: =AL26/W26 -> 0 | AL26: 0 | AM26: =W26-AL26 -> 900000 | AN26: =AM26/100000 -> 9 | AO26: Loan/Finance | AP26: SBI | AQ26: Walk-in | AR26: Yes | AS26: {=VLOOKUP($A26,Feedback[],{2,4,5,6,7},FALSE)} -> FB0018 | AT26: 5 | AU26: 9 | AV26: Dealer Visit | AW26: None
A27: ORD00026 | B27: 45321 | C27: =TEXT(B27,"mmm") -> Jan | D27: =TEXT(B27,"yyyy") -> 2024 | E27: 45354 | F27: Delivered | G27: =IF(E27=0,"",E27-B27) -> 33 | H27: CU0550 | I27: =VLOOKUP($H27,Customers!$A$1:$I$721,2,FALSE) -> Sachin Bose | J27: =VLOOKUP($H27,Customers!$A$1:$I$721,3,FALSE) -> Male | K27: =VLOOKUP($H27,Customers!$A$1:$I$721,4,FALSE) -> 31 | L27: =VLOOKUP($H27,Customers!$A$1:$I$721,5,FALSE) -> Jaipur | M27: =VLOOKUP($H27,Customers!$A$1:$I$721,6,FALSE) -> Rajasthan | N27: =VLOOKUP($H27,Customers!$A$1:$I$721,7,FALSE) -> Teacher | O27: =VLOOKUP($H27,Customers!$A$1:$I$721,8,FALSE) -> 500000 | P27: =VLOOKUP($H27,Customers!$A$1:$I$721,9,FALSE) -> Individual | Q27: C009 | R27: {=VLOOKUP($Q27,Cars[],{2,3,4,5,6,7,8,9},FALSE)} -> Hyundai | S27: i20 | T27: Hatchback | U27: Petrol | V27: Automatic | W27: 780000 | X27: 2023 | Y27: 2 | Z27: D006 | AA27: =VLOOKUP(Z27,Dealers[],5,FALSE) -> North | AB27: {=VLOOKUP($Z27,Dealers[],{2,7,8,9},FALSE)} -> Jaipur Wheels | AC27: 2015 | AD27: 3000 | AE27: 3.5 | AF27: S017 | AG27: =VLOOKUP($AF27,SalesPerson[],2,FALSE) -> Mohit Yadav | AH27: =_xlfn.XLOOKUP(AG27,Salespersons!$B:$B,Salespersons!$G:$G,,0) -> 8 | AI27: =_xlfn.XLOOKUP(AG27,Salespersons!$B:$B,Salespersons!$I:$I,,0) -> True | AJ27: White | AK27: =AL27/W27 -> 0 | AL27: 0 | AM27: =W27-AL27 -> 780000 | AN27: =AM27/100000 -> 7.8 | AO27: Loan/Finance | AP27: Axis Bank | AQ27: Test Drive Campaign | AR27: No | AS27: No Feedback | AT27: No Feedback | AU27: No Feedback | AV27: No Feedback | AW27: No Feedback
A28: ORD00027 | B28: 45321 | C28: =TEXT(B28,"mmm") -> Jan | D28: =TEXT(B28,"yyyy") -> 2024 | E28: 45349 | F28: Delivered | G28: =IF(E28=0,"",E28-B28) -> 28 | H28: CU0602 | I28: =VLOOKUP($H28,Customers!$A$1:$I$721,2,FALSE) -> Siddharth Khanna | J28: =VLOOKUP($H28,Customers!$A$1:$I$721,3,FALSE) -> Male | K28: =VLOOKUP($H28,Customers!$A$1:$I$721,4,FALSE) -> 30 | L28: =VLOOKUP($H28,Customers!$A$1:$I$721,5,FALSE) -> Hyderabad | M28: =VLOOKUP($H28,Customers!$A$1:$I$721,6,FALSE) -> Telangana | N28: =VLOOKUP($H28,Customers!$A$1:$I$721,7,FALSE) -> Salaried - Private | O28: =VLOOKUP($H28,Customers!$A$1:$I$721,8,FALSE) -> 550000 | P28: =VLOOKUP($H28,Customers!$A$1:$I$721,9,FALSE) -> Individual | Q28: C004 | R28: {=VLOOKUP($Q28,Cars[],{2,3,4,5,6,7,8,9},FALSE)} -> Maruti Suzuki | S28: Dzire | T28: Sedan | U28: Petrol | V28: Manual | W28: 690000 | X28: 2024 | Y28: 3 | Z28: D018 | AA28: =VLOOKUP(Z28,Dealers[],5,FALSE) -> South | AB28: {=VLOOKUP($Z28,Dealers[],{2,7,8,9},FALSE)} -> Hyderabad Automobiles | AC28: 2019 | AD28: 4500 | AE28: 3.8 | AF28: S054 | AG28: =VLOOKUP($AF28,SalesPerson[],2,FALSE) -> Gaurav Shah | AH28: =_xlfn.XLOOKUP(AG28,Salespersons!$B:$B,Salespersons!$G:$G,,0) -> 4 | AI28: =_xlfn.XLOOKUP(AG28,Salespersons!$B:$B,Salespersons!$I:$I,,0) -> True | AJ28: Silver | AK28: =AL28/W28 -> 0 | AL28: 0 | AM28: =W28-AL28 -> 690000 | AN28: =AM28/100000 -> 6.9 | AO28: Cash | AP28: N/A | AQ28: Online Website | AR28: No | AS28: No Feedback | AT28: No Feedback | AU28: No Feedback | AV28: No Feedback | AW28: No Feedback
A29: ORD00028 | B29: 45322 | C29: =TEXT(B29,"mmm") -> Jan | D29: =TEXT(B29,"yyyy") -> 2024 | E29: 45354 | F29: Delivered | G29: =IF(E29=0,"",E29-B29) -> 32 | H29: CU0337 | I29: =VLOOKUP($H29,Customers!$A$1:$I$721,2,FALSE) -> Mohit Bose | J29: =VLOOKUP($H29,Customers!$A$1:$I$721,3,FALSE) -> Male | K29: =VLOOKUP($H29,Customers!$A$1:$I$721,4,FALSE) -> 47 | L29: =VLOOKUP($H29,Customers!$A$1:$I$721,5,FALSE) -> Gurugram | M29: =VLOOKUP($H29,Customers!$A$1:$I$721,6,FALSE) -> Haryana | N29: =VLOOKUP($H29,Customers!$A$1:$I$721,7,FALSE) -> Retired | O29: =VLOOKUP($H29,Customers!$A$1:$I$721,8,FALSE) -> 350000 | P29: =VLOOKUP($H29,Customers!$A$1:$I$721,9,FALSE) -> Individual | Q29: C029 | R29: {=VLOOKUP($Q29,Cars[],{2,3,4,5,6,7,8,9},FALSE)} -> Honda | S29: Amaze | T29: Sedan | U29: Petrol | V29: Manual | W29: 800000 | X29: 2024 | Y29: 3 | Z29: D015 | AA29: =VLOOKUP(Z29,Dealers[],5,FALSE) -> South | AB29: {=VLOOKUP($Z29,Dealers[],{2,7,8,9},FALSE)} -> Mysuru Auto Hub | AC29: 2006 | AD29: 4500 | AE29: 4.6 | AF29: S046 | AG29: =VLOOKUP($AF29,SalesPerson[],2,FALSE) -> Tanvi Reddy | AH29: =_xlfn.XLOOKUP(AG29,Salespersons!$B:$B,Salespersons!$G:$G,,0) -> 4 | AI29: =_xlfn.XLOOKUP(AG29,Salespersons!$B:$B,Salespersons!$I:$I,,0) -> True | AJ29: Black | AK29: =AL29/W29 -> 0.02375 | AL29: 19000 | AM29: =W29-AL29 -> 781000 | AN29: =AM29/100000 -> 7.81 | AO29: Loan/Finance | AP29: ICICI Bank | AQ29: Auto Expo/Event | AR29: No | AS29: {=VLOOKUP($A29,Feedback[],{2,4,5,6,7},FALSE)} -> FB0019 | AT29: 5 | AU29: 10 | AV29: Email | AW29: None
A30: ORD00029 | B30: 45325 | C30: =TEXT(B30,"mmm") -> Feb | D30: =TEXT(B30,"yyyy") -> 2024 | E30: 45357 | F30: Delivered | G30: =IF(E30=0,"",E30-B30) -> 32 | H30: CU0305 | I30: =VLOOKUP($H30,Customers!$A$1:$I$721,2,FALSE) -> Sneha Mishra | J30: =VLOOKUP($H30,Customers!$A$1:$I$721,3,FALSE) -> Female | K30: =VLOOKUP($H30,Customers!$A$1:$I$721,4,FALSE) -> 40 | L30: =VLOOKUP($H30,Customers!$A$1:$I$721,5,FALSE) -> Bengaluru | M30: =VLOOKUP($H30,Customers!$A$1:$I$721,6,FALSE) -> Karnataka | N30: =VLOOKUP($H30,Customers!$A$1:$I$721,7,FALSE) -> Salaried - Private | O30: =VLOOKUP($H30,Customers!$A$1:$I$721,8,FALSE) -> 760000 | P30: =VLOOKUP($H30,Customers!$A$1:$I$721,9,FALSE) -> Individual | Q30: C009 | R30: {=VLOOKUP($Q30,Cars[],{2,3,4,5,6,7,8,9},FALSE)} -> Hyundai | S30: i20 | T30: Hatchback | U30: Petrol | V30: Automatic | W30: 780000 | X30: 2023 | Y30: 2 | Z30: D014 | AA30: =VLOOKUP(Z30,Dealers[],5,FALSE) -> South | AB30: {=VLOOKUP($Z30,Dealers[],{2,7,8,9},FALSE)} -> Bengaluru Auto Hub | AC30: 2013 | AD30: 12000 | AE30: 4.4 | AF30: S043 | AG30: =VLOOKUP($AF30,SalesPerson[],2,FALSE) -> Yash Singh | AH30: =_xlfn.XLOOKUP(AG30,Salespersons!$B:$B,Salespersons!$G:$G,,0) -> 4 | AI30: =_xlfn.XLOOKUP(AG30,Salespersons!$B:$B,Salespersons!$I:$I,,0) -> True | AJ30: Black | AK30: =AL30/W30 -> 0 | AL30: 0 | AM30: =W30-AL30 -> 780000 | AN30: =AM30/100000 -> 7.8 | AO30: Cash | AP30: N/A | AQ30: Corporate Tie-up | AR30: Yes | AS30: No Feedback | AT30: No Feedback | AU30: No Feedback | AV30: No Feedback | AW30: No Feedback
A31: ORD00030 | B31: 45326 | C31: =TEXT(B31,"mmm") -> Feb | D31: =TEXT(B31,"yyyy") -> 2024 | E31: 45333 | F31: Delivered | G31: =IF(E31=0,"",E31-B31) -> 7 | H31: CU0716 | I31: =VLOOKUP($H31,Customers!$A$1:$I$721,2,FALSE) -> Anjali Rao | J31: =VLOOKUP($H31,Customers!$A$1:$I$721,3,FALSE) -> Female | K31: =VLOOKUP($H31,Customers!$A$1:$I$721,4,FALSE) -> 56 | L31: =VLOOKUP($H31,Customers!$A$1:$I$721,5,FALSE) -> Lucknow | M31: =VLOOKUP($H31,Customers!$A$1:$I$721,6,FALSE) -> Uttar Pradesh | N31: =VLOOKUP($H31,Customers!$A$1:$I$721,7,FALSE) -> Engineer | O31: =VLOOKUP($H31,Customers!$A$1:$I$721,8,FALSE) -> 1140000 | P31: =VLOOKUP($H31,Customers!$A$1:$I$721,9,FALSE) -> Individual | Q31: C015 | R31: {=VLOOKUP($Q31,Cars[],{2,3,4,5,6,7,8,9},FALSE)} -> Tata | S31: Punch | T31: SUV | U31: Petrol | V31: Manual | W31: 650000 | X31: 2021 | Y31: 3 | Z31: D007 | AA31: =VLOOKUP(Z31,Dealers[],5,FALSE) -> North | AB31: {=VLOOKUP($Z31,Dealers[],{2,7,8,9},FALSE)} -> Lucknow Motors | AC31: 2013 | AD31: 3000 | AE31: 4.4 | AF31: S020 | AG31: =VLOOKUP($AF31,SalesPerson[],2,FALSE) -> Tarun Patel | AH31: =_xlfn.XLOOKUP(AG31,Salespersons!$B:$B,Salespersons!$G:$G,,0) -> 4 | AI31: =_xlfn.XLOOKUP(AG31,Salespersons!$B:$B,Salespersons!$I:$I,,0) -> True | AJ31: Grey | AK31: =AL31/W31 -> 0.041538462 | AL31: 27000 | AM31: =W31-AL31 -> 623000 | AN31: =AM31/100000 -> 6.23 | AO31: Cash | AP31: N/A | AQ31: Corporate Tie-up | AR31: Yes | AS31: {=VLOOKUP($A31,Feedback[],{2,4,5,6,7},FALSE)} -> FB0020 | AT31: 4 | AU31: 8 | AV31: Dealer Visit | AW31: None
A32: ORD00031 | B32: 45326 | C32: =TEXT(B32,"mmm") -> Feb | D32: =TEXT(B32,"yyyy") -> 2024 | E32: 45349 | F32: Delivered | G32: =IF(E32=0,"",E32-B32) -> 23 | H32: CU0506 | I32: =VLOOKUP($H32,Customers!$A$1:$I$721,2,FALSE) -> Sandeep Verma | J32: =VLOOKUP($H32,Customers!$A$1:$I$721,3,FALSE) -> Male | K32: =VLOOKUP($H32,Customers!$A$1:$I$721,4,FALSE) -> 54 | L32: =VLOOKUP($H32,Customers!$A$1:$I$721,5,FALSE) -> Pune | M32: =VLOOKUP($H32,Customers!$A$1:$I$721,6,FALSE) -> Maharashtra | N32: =VLOOKUP($H32,Customers!$A$1:$I$721,7,FALSE) -> Business Owner | O32: =VLOOKUP($H32,Customers!$A$1:$I$721,8,FALSE) -> 1830000 | P32: =VLOOKUP($H32,Customers!$A$1:$I$721,9,FALSE) -> Individual | Q32: C010 | R32: {=VLOOKUP($Q32,Cars[],{2,3,4,5,6,7,8,9},FALSE)} -> Hyundai | S32: Venue | T32: SUV | U32: Petrol | V32: Manual | W32: 800000 | X32: 2022 | Y32: 3 | Z32: D009 | AA32: =VLOOKUP(Z32,Dealers[],5,FALSE) -> West | AB32: {=VLOOKUP($Z32,Dealers[],{2,7,8,9},FALSE)} -> Mumbai Autoplex | AC32: 2011 | AD32: 12000 | AE32: 3.5 | AF32: S028 | AG32: =VLOOKUP($AF32,SalesPerson[],2,FALSE) -> Ankit Rao | AH32: =_xlfn.XLOOKUP(AG32,Salespersons!$B:$B,Salespersons!$G:$G,,0) -> 7 | AI32: =_xlfn.XLOOKUP(AG32,Salespersons!$B:$B,Salespersons!$I:$I,,0) -> True | AJ32: Black | AK32: =AL32/W32 -> 0 | AL32: 0 | AM32: =W32-AL32 -> 800000 | AN32: =AM32/100000 -> 8 | AO32: Cash | AP32: N/A | AQ32: Online Website | AR32: No | AS32: {=VLOOKUP($A32,Feedback[],{2,4,5,6,7},FALSE)} -> FB0021 | AT32: 4 | AU32: 10 | AV32: Dealer Visit | AW32: None
A33: ORD00032 | B33: 45327 | C33: =TEXT(B33,"mmm") -> Feb | D33: =TEXT(B33,"yyyy") -> 2024 | E33: 45355 | F33: Delivered | G33: =IF(E33=0,"",E33-B33) -> 28 | H33: CU0213 | I33: =VLOOKUP($H33,Customers!$A$1:$I$721,2,FALSE) -> Nisha Sharma | J33: =VLOOKUP($H33,Customers!$A$1:$I$721,3,FALSE) -> Female | K33: =VLOOKUP($H33,Customers!$A$1:$I$721,4,FALSE) -> 21 | L33: =VLOOKUP($H33,Customers!$A$1:$I$721,5,FALSE) -> Bhopal | M33: =VLOOKUP($H33,Customers!$A$1:$I$721,6,FALSE) -> Madhya Pradesh | N33: =VLOOKUP($H33,Customers!$A$1:$I$721,7,FALSE) -> Business Owner | O33: =VLOOKUP($H33,Customers!$A$1:$I$721,8,FALSE) -> 1760000 | P33: =VLOOKUP($H33,Customers!$A$1:$I$721,9,FALSE) -> Individual | Q33: C013 | R33: {=VLOOKUP($Q33,Cars[],{2,3,4,5,6,7,8,9},FALSE)} -> Hyundai | S33: Alcazar | T33: SUV | U33: Diesel | V33: Automatic | W33: 1700000 | X33: 2024 | Y33: 2 | Z33: D024 | AA33: =VLOOKUP(Z33,Dealers[],5,FALSE) -> Central | AB33: {=VLOOKUP($Z33,Dealers[],{2,7,8,9},FALSE)} -> Bhopal Autoplex | AC33: 2013 | AD33: 12000 | AE33: 3.9 | AF33: S073 | AG33: =VLOOKUP($AF33,SalesPerson[],2,FALSE) -> Sneha Iyer | AH33: =_xlfn.XLOOKUP(AG33,Salespersons!$B:$B,Salespersons!$G:$G,,0) -> 4 | AI33: =_xlfn.XLOOKUP(AG33,Salespersons!$B:$B,Salespersons!$I:$I,,0) -> True | AJ33: Red | AK33: =AL33/W33 -> 0.037647059 | AL33: 64000 | AM33: =W33-AL33 -> 1636000 | AN33: =AM33/100000 -> 16.36 | AO33: Exchange + Loan | AP33: Axis Bank | AQ33: Social Media | AR33: Yes | AS33: {=VLOOKUP($A33,Feedback[],{2,4,5,6,7},FALSE)} -> FB0022 | AT33: 5 | AU33: 9 | AV33: Online Survey | AW33: None
A34: ORD00033 | B34: 45327 | C34: =TEXT(B34,"mmm") -> Feb | D34: =TEXT(B34,"yyyy") -> 2024 | E34: 45345 | F34: Delivered | G34: =IF(E34=0,"",E34-B34) -> 18 | H34: CU0011 | I34: =VLOOKUP($H34,Customers!$A$1:$I$721,2,FALSE) -> Jatin Sharma | J34: =VLOOKUP($H34,Customers!$A$1:$I$721,3,FALSE) -> Male | K34: =VLOOKUP($H34,Customers!$A$1:$I$721,4,FALSE) -> 29 | L34: =VLOOKUP($H34,Customers!$A$1:$I$721,5,FALSE) -> Guwahati | M34: =VLOOKUP($H34,Customers!$A$1:$I$721,6,FALSE) -> Assam | N34: =VLOOKUP($H34,Customers!$A$1:$I$721,7,FALSE) -> Retired | O34: =VLOOKUP($H34,Customers!$A$1:$I$721,8,FALSE) -> 660000 | P34: =VLOOKUP($H34,Customers!$A$1:$I$721,9,FALSE) -> Individual | Q34: C005 | R34: {=VLOOKUP($Q34,Cars[],{2,3,4,5,6,7,8,9},FALSE)} -> Maruti Suzuki | S34: Brezza | T34: SUV | U34: Petrol | V34: Automatic | W34: 900000 | X34: 2022 | Y34: 3 | Z34: D023 | AA34: =VLOOKUP(Z34,Dealers[],5,FALSE) -> East | AB34: {=VLOOKUP($Z34,Dealers[],{2,7,8,9},FALSE)} -> Guwahati Automobiles | AC34: 2005 | AD34: 12000 | AE34: 4.4 | AF34: S070 | AG34: =VLOOKUP($AF34,SalesPerson[],2,FALSE) -> Tarun Mehta | AH34: =_xlfn.XLOOKUP(AG34,Salespersons!$B:$B,Salespersons!$G:$G,,0) -> 4 | AI34: =_xlfn.XLOOKUP(AG34,Salespersons!$B:$B,Salespersons!$I:$I,,0) -> True | AJ34: Grey | AK34: =AL34/W34 -> 0.037777778 | AL34: 34000 | AM34: =W34-AL34 -> 866000 | AN34: =AM34/100000 -> 8.66 | AO34: Exchange + Loan | AP34: Axis Bank | AQ34: Social Media | AR34: Yes | AS34: No Feedback | AT34: No Feedback | AU34: No Feedback | AV34: No Feedback | AW34: No Feedback
A35: ORD00034 | B35: 45327 | C35: =TEXT(B35,"mmm") -> Feb | D35: =TEXT(B35,"yyyy") -> 2024 | E35: 45355 | F35: Delivered | G35: =IF(E35=0,"",E35-B35) -> 28 | H35: CU0483 | I35: =VLOOKUP($H35,Customers!$A$1:$I$721,2,FALSE) -> Ritu Reddy | J35: =VLOOKUP($H35,Customers!$A$1:$I$721,3,FALSE) -> Female | K35: =VLOOKUP($H35,Customers!$A$1:$I$721,4,FALSE) -> 50 | L35: =VLOOKUP($H35,Customers!$A$1:$I$721,5,FALSE) -> Chennai | M35: =VLOOKUP($H35,Customers!$A$1:$I$721,6,FALSE) -> Tamil Nadu | N35: =VLOOKUP($H35,Customers!$A$1:$I$721,7,FALSE) -> Farmer | O35: =VLOOKUP($H35,Customers!$A$1:$I$721,8,FALSE) -> 850000 | P35: =VLOOKUP($H35,Customers!$A$1:$I$721,9,FALSE) -> Individual | Q35: C028 | R35: {=VLOOKUP($Q35,Cars[],{2,3,4,5,6,7,8,9},FALSE)} -> Honda | S35: City | T35: Sedan | U35: Petrol | V35: Automatic | W35: 1250000 | X35: 2023 | Y35: 4 | Z35: D016 | AA35: =VLOOKUP(Z35,Dealers[],5,FALSE) -> South | AB35: {=VLOOKUP($Z35,Dealers[],{2,7,8,9},FALSE)} -> Chennai Wheels | AC35: 2007 | AD35: 4500 | AE35: 4.7 | AF35: S048 | AG35: =VLOOKUP($AF35,SalesPerson[],2,FALSE) -> Kunal Pillai | AH35: =_xlfn.XLOOKUP(AG35,Salespersons!$B:$B,Salespersons!$G:$G,,0) -> 5 | AI35: =_xlfn.XLOOKUP(AG35,Salespersons!$B:$B,Salespersons!$I:$I,,0) -> True | AJ35: White | AK35: =AL35/W35 -> 0.0248 | AL35: 31000 | AM35: =W35-AL35 -> 1219000 | AN35: =AM35/100000 -> 12.19 | AO35: Loan/Finance | AP35: HDFC Bank | AQ35: Corporate Tie-up | AR35: Yes | AS35: {=VLOOKUP($A35,Feedback[],{2,4,5,6,7},FALSE)} -> FB0023 | AT35: 3 | AU35: 5 | AV35: Dealer Visit | AW35: None
A36: ORD00035 | B36: 45332 | C36: =TEXT(B36,"mmm") -> Feb | D36: =TEXT(B36,"yyyy") -> 2024 | E36: 45338 | F36: Delivered | G36: =IF(E36=0,"",E36-B36) -> 6 | H36: CU0694 | I36: =VLOOKUP($H36,Customers!$A$1:$I$721,2,FALSE) -> Ashok Gupta | J36: =VLOOKUP($H36,Customers!$A$1:$I$721,3,FALSE) -> Male | K36: =VLOOKUP($H36,Customers!$A$1:$I$721,4,FALSE) -> 35 | L36: =VLOOKUP($H36,Customers!$A$1:$I$721,5,FALSE) -> Noida | M36: =VLOOKUP($H36,Customers!$A$1:$I$721,6,FALSE) -> Uttar Pradesh | N36: =VLOOKUP($H36,Customers!$A$1:$I$721,7,FALSE) -> Engineer | O36: =VLOOKUP($H36,Customers!$A$1:$I$721,8,FALSE) -> 1850000 | P36: =VLOOKUP($H36,Customers!$A$1:$I$721,9,FALSE) -> Individual | Q36: C006 | R36: {=VLOOKUP($Q36,Cars[],{2,3,4,5,6,7,8,9},FALSE)} -> Maruti Suzuki | S36: Ertiga | T36: MPV | U36: CNG | V36: Manual | W36: 900000 | X36: 2022 | Y36: 3 | Z36: D007 | AA36: =VLOOKUP(Z36,Dealers[],5,FALSE) -> North | AB36: {=VLOOKUP($Z36,Dealers[],{2,7,8,9},FALSE)} -> Lucknow Motors | AC36: 2013 | AD36: 3000 | AE36: 4.4 | AF36: S020 | AG36: =VLOOKUP($AF36,SalesPerson[],2,FALSE) -> Tarun Patel | AH36: =_xlfn.XLOOKUP(AG36,Salespersons!$B:$B,Salespersons!$G:$G,,0) -> 4 | AI36: =_xlfn.XLOOKUP(AG36,Salespersons!$B:$B,Salespersons!$I:$I,,0) -> True | AJ36: Red | AK36: =AL36/W36 -> 0.032222222 | AL36: 29000 | AM36: =W36-AL36 -> 871000 | AN36: =AM36/100000 -> 8.71 | AO36: Cash | AP36: N/A | AQ36: Auto Expo/Event | AR36: No | AS36: No Feedback | AT36: No Feedback | AU36: No Feedback | AV36: No Feedback | AW36: No Feedback
